ERROR 2018-10-23 21:05:49,660 exception 80 Invalid HTTP_HOST header: '127.0.0.1:8000'. You may need to add '127.0.0.1' to ALLOWED_HOSTS.
WARNING 2018-10-23 21:05:49,710 base 152 Not Found: /mobiles/16625139066/count/
WARNING 2018-10-23 21:05:49,728 basehttp 124 "GET /mobiles/16625139066/count/ HTTP/1.1" 404 2202
WARNING 2018-10-23 21:05:49,795 base 152 Not Found: /mobiles/16625139066/count/
WARNING 2018-10-23 21:05:49,811 basehttp 124 "GET /mobiles/16625139066/count/ HTTP/1.1" 404 2202
WARNING 2018-10-23 21:05:49,980 basehttp 124 "GET /sms_code/16625139066/ HTTP/1.1" 400 70605
ERROR 2018-10-23 21:09:28,740 exception 80 Invalid HTTP_HOST header: '127.0.0.1:8000'. You may need to add '127.0.0.1' to ALLOWED_HOSTS.
WARNING 2018-10-23 21:09:28,764 base 152 Not Found: /mobiles/16625139066/count/
WARNING 2018-10-23 21:09:28,772 basehttp 124 "GET /mobiles/16625139066/count/ HTTP/1.1" 404 2202
WARNING 2018-10-23 21:09:28,973 basehttp 124 "GET /sms_code/16625139066/ HTTP/1.1" 400 70707
ERROR 2018-10-23 21:12:24,615 exception 80 Invalid HTTP_HOST header: '127.0.0.1:8000'. You may need to add '127.0.0.1' to ALLOWED_HOSTS.
WARNING 2018-10-23 21:12:24,645 base 152 Not Found: /mobiles/16625139066/count/
WARNING 2018-10-23 21:12:24,660 basehttp 124 "GET /mobiles/16625139066/count/ HTTP/1.1" 404 2202
WARNING 2018-10-23 21:12:24,706 base 152 Not Found: /mobiles/16625139066/count/
WARNING 2018-10-23 21:12:24,721 basehttp 124 "GET /mobiles/16625139066/count/ HTTP/1.1" 404 2202
WARNING 2018-10-23 21:12:24,869 basehttp 124 "GET /sms_code/16625139066/ HTTP/1.1" 400 70707
WARNING 2018-10-23 21:13:10,327 base 152 Not Found: /mobiles/16625139066/count/
WARNING 2018-10-23 21:13:10,335 basehttp 124 "GET /mobiles/16625139066/count/ HTTP/1.1" 404 2202
ERROR 2018-10-23 21:13:10,426 exception 80 Invalid HTTP_HOST header: '127.0.0.1:8000'. You may need to add '127.0.0.1' to ALLOWED_HOSTS.
WARNING 2018-10-23 21:13:10,447 base 152 Not Found: /mobiles/16625139066/count/
WARNING 2018-10-23 21:13:10,459 basehttp 124 "GET /mobiles/16625139066/count/ HTTP/1.1" 404 2202
WARNING 2018-10-23 21:13:10,691 basehttp 124 "GET /sms_code/16625139066/ HTTP/1.1" 400 70707
ERROR 2018-10-23 21:15:51,603 exception 80 Invalid HTTP_HOST header: '127.0.0.1:8000'. You may need to add '127.0.0.1' to ALLOWED_HOSTS.
WARNING 2018-10-23 21:15:51,649 basehttp 124 "GET /sms_code/16625139066/ HTTP/1.1" 400 70709
WARNING 2018-10-23 21:15:57,077 base 152 Not Found: /mobiles/16625139066/count/
WARNING 2018-10-23 21:15:57,084 basehttp 124 "GET /mobiles/16625139066/count/ HTTP/1.1" 404 2202
WARNING 2018-10-23 21:15:57,088 base 152 Not Found: /mobiles/16625139066/count/
WARNING 2018-10-23 21:15:57,088 basehttp 124 "GET /mobiles/16625139066/count/ HTTP/1.1" 404 2202
WARNING 2018-10-23 21:18:41,713 base 152 Not Found: /mobiles/16625139066/count/
WARNING 2018-10-23 21:18:41,717 basehttp 124 "GET /mobiles/16625139066/count/ HTTP/1.1" 404 2202
WARNING 2018-10-23 21:18:41,753 base 152 Not Found: /mobiles/16625139066/count/
WARNING 2018-10-23 21:18:41,754 basehttp 124 "GET /mobiles/16625139066/count/ HTTP/1.1" 404 2202
ERROR 2018-10-23 21:18:42,222 exception 135 Internal Server Error: /sms_code/16625139066/
Traceback (most recent call last):
  File "/home/python/.virtualenvs/mydjango_py3_1.11/lib/python3.5/site-packages/rest_framework/views.py", line 480, in dispatch
    response = handler(request, *args, **kwargs)
  File "/home/python/Desktop/MyProject/meiduo/meiduo/apps/verifications/views.py", line 33, in get
    send_sms_code.delay(mobile, sms_code, constants.SMS_CODE_EXPIRES/60, 1)
  File "/home/python/.virtualenvs/mydjango_py3_1.11/lib/python3.5/site-packages/celery/app/task.py", line 408, in delay
    return self.apply_async(args, kwargs)
  File "/home/python/.virtualenvs/mydjango_py3_1.11/lib/python3.5/site-packages/celery/app/task.py", line 513, in apply_async
    check_arguments(*(args or ()), **(kwargs or {}))
TypeError: send_sms_code() takes 3 positional arguments but 4 were given

During handling of the above exception, another exception occurred:

Traceback (most recent call last):
  File "/home/python/.virtualenvs/mydjango_py3_1.11/lib/python3.5/site-packages/rest_framework/settings.py", line 183, in import_from_string
    module = import_module(module_path)
  File "/home/python/.virtualenvs/mydjango_py3_1.11/lib/python3.5/importlib/__init__.py", line 126, in import_module
    return _bootstrap._gcd_import(name[level:], package, level)
  File "<frozen importlib._bootstrap>", line 986, in _gcd_import
  File "<frozen importlib._bootstrap>", line 969, in _find_and_load
  File "<frozen importlib._bootstrap>", line 956, in _find_and_load_unlocked
ImportError: No module named 'utils.exceptions'

During handling of the above exception, another exception occurred:

Traceback (most recent call last):
  File "/home/python/.virtualenvs/mydjango_py3_1.11/lib/python3.5/site-packages/django/core/handlers/exception.py", line 41, in inner
    response = get_response(request)
  File "/home/python/.virtualenvs/mydjango_py3_1.11/lib/python3.5/site-packages/django/core/handlers/base.py", line 187, in _get_response
    response = self.process_exception_by_middleware(e, request)
  File "/home/python/.virtualenvs/mydjango_py3_1.11/lib/python3.5/site-packages/django/core/handlers/base.py", line 185, in _get_response
    response = wrapped_callback(request, *callback_args, **callback_kwargs)
  File "/home/python/.virtualenvs/mydjango_py3_1.11/lib/python3.5/site-packages/django/views/decorators/csrf.py", line 58, in wrapped_view
    return view_func(*args, **kwargs)
  File "/home/python/.virtualenvs/mydjango_py3_1.11/lib/python3.5/site-packages/django/views/generic/base.py", line 68, in view
    return self.dispatch(request, *args, **kwargs)
  File "/home/python/.virtualenvs/mydjango_py3_1.11/lib/python3.5/site-packages/rest_framework/views.py", line 483, in dispatch
    response = self.handle_exception(exc)
  File "/home/python/.virtualenvs/mydjango_py3_1.11/lib/python3.5/site-packages/rest_framework/views.py", line 437, in handle_exception
    exception_handler = self.get_exception_handler()
  File "/home/python/.virtualenvs/mydjango_py3_1.11/lib/python3.5/site-packages/rest_framework/views.py", line 288, in get_exception_handler
    return self.settings.EXCEPTION_HANDLER
  File "/home/python/.virtualenvs/mydjango_py3_1.11/lib/python3.5/site-packages/rest_framework/settings.py", line 227, in __getattr__
    val = perform_import(val, attr)
  File "/home/python/.virtualenvs/mydjango_py3_1.11/lib/python3.5/site-packages/rest_framework/settings.py", line 170, in perform_import
    return import_from_string(val, setting_name)
  File "/home/python/.virtualenvs/mydjango_py3_1.11/lib/python3.5/site-packages/rest_framework/settings.py", line 187, in import_from_string
    raise ImportError(msg)
ImportError: Could not import 'utils.exceptions.exception_handler' for API setting 'EXCEPTION_HANDLER'. ImportError: No module named 'utils.exceptions'.
ERROR 2018-10-23 21:18:42,318 basehttp 124 "GET /sms_code/16625139066/ HTTP/1.1" 500 130286
WARNING 2018-10-23 21:20:05,073 base 152 Not Found: /mobiles/16625139066/count/
WARNING 2018-10-23 21:20:05,081 basehttp 124 "GET /mobiles/16625139066/count/ HTTP/1.1" 404 2202
WARNING 2018-10-23 21:20:05,108 base 152 Not Found: /mobiles/16625139066/count/
WARNING 2018-10-23 21:20:05,109 basehttp 124 "GET /mobiles/16625139066/count/ HTTP/1.1" 404 2202
ERROR 2018-10-23 21:20:05,186 exception 135 Internal Server Error: /sms_code/16625139066/
Traceback (most recent call last):
  File "/home/python/.virtualenvs/mydjango_py3_1.11/lib/python3.5/site-packages/django/core/handlers/exception.py", line 41, in inner
    response = get_response(request)
  File "/home/python/.virtualenvs/mydjango_py3_1.11/lib/python3.5/site-packages/django/core/handlers/base.py", line 187, in _get_response
    response = self.process_exception_by_middleware(e, request)
  File "/home/python/.virtualenvs/mydjango_py3_1.11/lib/python3.5/site-packages/django/core/handlers/base.py", line 185, in _get_response
    response = wrapped_callback(request, *callback_args, **callback_kwargs)
  File "/home/python/.virtualenvs/mydjango_py3_1.11/lib/python3.5/site-packages/django/views/decorators/csrf.py", line 58, in wrapped_view
    return view_func(*args, **kwargs)
  File "/home/python/.virtualenvs/mydjango_py3_1.11/lib/python3.5/site-packages/django/views/generic/base.py", line 68, in view
    return self.dispatch(request, *args, **kwargs)
  File "/home/python/.virtualenvs/mydjango_py3_1.11/lib/python3.5/site-packages/rest_framework/views.py", line 483, in dispatch
    response = self.handle_exception(exc)
  File "/home/python/.virtualenvs/mydjango_py3_1.11/lib/python3.5/site-packages/rest_framework/views.py", line 443, in handle_exception
    self.raise_uncaught_exception(exc)
  File "/home/python/.virtualenvs/mydjango_py3_1.11/lib/python3.5/site-packages/rest_framework/views.py", line 480, in dispatch
    response = handler(request, *args, **kwargs)
  File "/home/python/Desktop/MyProject/meiduo/meiduo/apps/verifications/views.py", line 33, in get
    send_sms_code.delay(mobile, sms_code, constants.SMS_CODE_EXPIRES/60, 1)
  File "/home/python/.virtualenvs/mydjango_py3_1.11/lib/python3.5/site-packages/celery/app/task.py", line 408, in delay
    return self.apply_async(args, kwargs)
  File "/home/python/.virtualenvs/mydjango_py3_1.11/lib/python3.5/site-packages/celery/app/task.py", line 513, in apply_async
    check_arguments(*(args or ()), **(kwargs or {}))
TypeError: send_sms_code() takes 3 positional arguments but 4 were given
ERROR 2018-10-23 21:20:05,408 basehttp 124 "GET /sms_code/16625139066/ HTTP/1.1" 500 18110
WARNING 2018-10-23 21:22:30,656 base 152 Not Found: /mobiles/16625139066/count/
WARNING 2018-10-23 21:22:30,659 basehttp 124 "GET /mobiles/16625139066/count/ HTTP/1.1" 404 2202
WARNING 2018-10-23 21:22:30,704 base 152 Not Found: /mobiles/16625139066/count/
WARNING 2018-10-23 21:22:30,705 basehttp 124 "GET /mobiles/16625139066/count/ HTTP/1.1" 404 2202
INFO 2018-10-23 21:22:30,939 basehttp 124 "GET /sms_code/16625139066/ HTTP/1.1" 200 16
WARNING 2018-10-23 21:23:23,042 base 152 Not Found: /mobiles/16625139066/count/
WARNING 2018-10-23 21:23:23,043 basehttp 124 "GET /mobiles/16625139066/count/ HTTP/1.1" 404 2202
WARNING 2018-10-23 21:23:23,136 base 152 Not Found: /mobiles/16625139066/count/
WARNING 2018-10-23 21:23:23,137 basehttp 124 "GET /mobiles/16625139066/count/ HTTP/1.1" 404 2202
INFO 2018-10-23 21:23:23,177 basehttp 124 "GET /sms_code/16625139066/ HTTP/1.1" 200 16
ERROR 2018-10-23 21:29:29,493 exception 80 Invalid HTTP_HOST header: '127.0.0.1:8000'. You may need to add '127.0.0.1' to ALLOWED_HOSTS.
WARNING 2018-10-23 21:29:29,737 base 152 Not Found: /mobiles/16625139066/count/
WARNING 2018-10-23 21:29:29,776 basehttp 124 "GET /mobiles/16625139066/count/ HTTP/1.1" 404 2202
WARNING 2018-10-23 21:29:29,840 base 152 Not Found: /mobiles/16625139066/count/
WARNING 2018-10-23 21:29:29,850 basehttp 124 "GET /mobiles/16625139066/count/ HTTP/1.1" 404 2202
WARNING 2018-10-23 21:29:30,215 basehttp 124 "GET /sms_code/16625139066/ HTTP/1.1" 400 70708
WARNING 2018-10-23 21:31:12,092 base 152 Not Found: /mobiles/16625139066/count/
WARNING 2018-10-23 21:31:12,103 basehttp 124 "GET /mobiles/16625139066/count/ HTTP/1.1" 404 2202
WARNING 2018-10-23 21:31:12,151 base 152 Not Found: /mobiles/16625139066/count/
WARNING 2018-10-23 21:31:12,155 basehttp 124 "GET /mobiles/16625139066/count/ HTTP/1.1" 404 2202
ERROR 2018-10-23 21:31:12,170 exception 80 Invalid HTTP_HOST header: '127.0.0.1:8000'. You may need to add '127.0.0.1' to ALLOWED_HOSTS.
WARNING 2018-10-23 21:31:12,256 basehttp 124 "GET /sms_code/16625139066/ HTTP/1.1" 400 70719
WARNING 2018-10-23 21:34:33,203 base 152 Not Found: /mobiles/16625139066/count/
ERROR 2018-10-23 21:34:33,205 exception 80 Invalid HTTP_HOST header: '127.0.0.1:8000'. You may need to add '127.0.0.1' to ALLOWED_HOSTS.
WARNING 2018-10-23 21:34:33,218 basehttp 124 "GET /mobiles/16625139066/count/ HTTP/1.1" 404 2202
WARNING 2018-10-23 21:34:33,308 basehttp 124 "GET /sms_code/16625139066/ HTTP/1.1" 400 70720
WARNING 2018-10-23 21:34:38,264 base 152 Not Found: /mobiles/16625139066/count/
ERROR 2018-10-23 21:34:38,264 exception 80 Invalid HTTP_HOST header: '127.0.0.1:8000'. You may need to add '127.0.0.1' to ALLOWED_HOSTS.
WARNING 2018-10-23 21:34:38,278 basehttp 124 "GET /mobiles/16625139066/count/ HTTP/1.1" 404 2202
WARNING 2018-10-23 21:34:38,346 basehttp 124 "GET /sms_code/16625139066/ HTTP/1.1" 400 70720
WARNING 2018-10-23 21:34:43,030 base 152 Not Found: /mobiles/16625139066/count/
ERROR 2018-10-23 21:34:43,034 exception 80 Invalid HTTP_HOST header: '127.0.0.1:8000'. You may need to add '127.0.0.1' to ALLOWED_HOSTS.
WARNING 2018-10-23 21:34:43,056 basehttp 124 "GET /mobiles/16625139066/count/ HTTP/1.1" 404 2202
WARNING 2018-10-23 21:34:43,158 basehttp 124 "GET /sms_code/16625139066/ HTTP/1.1" 400 70720
ERROR 2018-10-23 21:42:41,984 exception 80 Invalid HTTP_HOST header: '127.0.0.1:8000'. You may need to add '127.0.0.1' to ALLOWED_HOSTS.
WARNING 2018-10-23 21:42:41,993 base 152 Not Found: /mobiles/16625139066/count/
WARNING 2018-10-23 21:42:42,009 basehttp 124 "GET /mobiles/16625139066/count/ HTTP/1.1" 404 2202
WARNING 2018-10-23 21:42:42,037 base 152 Not Found: /mobiles/16625139066/count/
WARNING 2018-10-23 21:42:42,050 basehttp 124 "GET /mobiles/16625139066/count/ HTTP/1.1" 404 2202
WARNING 2018-10-23 21:42:42,251 basehttp 124 "GET /sms_code/16625139066/ HTTP/1.1" 400 70719
WARNING 2018-10-23 21:44:15,166 base 152 Not Found: /mobiles/16625139066/count/
WARNING 2018-10-23 21:44:15,171 basehttp 124 "GET /mobiles/16625139066/count/ HTTP/1.1" 404 2202
WARNING 2018-10-23 21:44:15,224 base 152 Not Found: /mobiles/16625139066/count/
WARNING 2018-10-23 21:44:15,226 basehttp 124 "GET /mobiles/16625139066/count/ HTTP/1.1" 404 2202
ERROR 2018-10-23 21:44:15,243 exception 80 Invalid HTTP_HOST header: '127.0.0.1:8000'. You may need to add '127.0.0.1' to ALLOWED_HOSTS.
WARNING 2018-10-23 21:44:15,360 basehttp 124 "GET /sms_code/16625139066/ HTTP/1.1" 400 70726
WARNING 2018-10-23 21:47:01,872 base 152 Not Found: /
WARNING 2018-10-23 21:47:01,881 basehttp 124 "GET / HTTP/1.1" 404 2106
WARNING 2018-10-23 21:47:02,279 base 152 Not Found: /favicon.ico
WARNING 2018-10-23 21:47:02,284 basehttp 124 "GET /favicon.ico HTTP/1.1" 404 2157
WARNING 2018-10-23 21:49:22,796 base 152 Not Found: /mobiles/16625139066/count/
WARNING 2018-10-23 21:49:22,797 basehttp 124 "GET /mobiles/16625139066/count/ HTTP/1.1" 404 2202
WARNING 2018-10-23 21:49:22,891 base 152 Not Found: /mobiles/16625139066/count/
WARNING 2018-10-23 21:49:22,891 basehttp 124 "GET /mobiles/16625139066/count/ HTTP/1.1" 404 2202
ERROR 2018-10-23 21:49:22,898 exception 80 Invalid HTTP_HOST header: '127.0.0.1:8000'. You may need to add '127.0.0.1' to ALLOWED_HOSTS.
WARNING 2018-10-23 21:49:23,057 basehttp 124 "GET /sms_code/16625139066/ HTTP/1.1" 400 70708
WARNING 2018-10-23 21:49:50,806 base 152 Not Found: /mobiles/16625139066/count/
WARNING 2018-10-23 21:49:50,807 basehttp 124 "GET /mobiles/16625139066/count/ HTTP/1.1" 404 2202
WARNING 2018-10-23 21:49:50,871 base 152 Not Found: /mobiles/16625139066/count/
WARNING 2018-10-23 21:49:50,871 basehttp 124 "GET /mobiles/16625139066/count/ HTTP/1.1" 404 2202
ERROR 2018-10-23 21:49:50,874 exception 80 Invalid HTTP_HOST header: '127.0.0.1:8000'. You may need to add '127.0.0.1' to ALLOWED_HOSTS.
WARNING 2018-10-23 21:49:50,991 basehttp 124 "GET /sms_code/16625139066/ HTTP/1.1" 400 70720
WARNING 2018-10-23 21:53:05,318 base 152 Not Found: /mobiles/16625139066/count/
WARNING 2018-10-23 21:53:05,320 basehttp 124 "GET /mobiles/16625139066/count/ HTTP/1.1" 404 2202
WARNING 2018-10-23 21:53:05,418 base 152 Not Found: /mobiles/16625139066/count/
WARNING 2018-10-23 21:53:05,419 basehttp 124 "GET /mobiles/16625139066/count/ HTTP/1.1" 404 2202
ERROR 2018-10-23 21:53:05,422 exception 80 Invalid HTTP_HOST header: '127.0.0.1:8000'. You may need to add '127.0.0.1' to ALLOWED_HOSTS.
WARNING 2018-10-23 21:53:05,540 basehttp 124 "GET /sms_code/16625139066/ HTTP/1.1" 400 70719
WARNING 2018-10-23 22:16:03,368 base 152 Not Found: /mobiles/16625139066/count/
WARNING 2018-10-23 22:16:03,379 basehttp 124 "GET /mobiles/16625139066/count/ HTTP/1.1" 404 2202
ERROR 2018-10-23 22:16:03,387 exception 80 Invalid HTTP_HOST header: '127.0.0.1:8000'. You may need to add '127.0.0.1' to ALLOWED_HOSTS.
WARNING 2018-10-23 22:16:03,420 base 152 Not Found: /mobiles/16625139066/count/
WARNING 2018-10-23 22:16:03,431 basehttp 124 "GET /mobiles/16625139066/count/ HTTP/1.1" 404 2202
WARNING 2018-10-23 22:16:03,551 basehttp 124 "GET /sms_code/16625139066/ HTTP/1.1" 400 70744
WARNING 2018-10-23 22:17:59,832 base 152 Not Found: /
WARNING 2018-10-23 22:17:59,834 basehttp 124 "GET / HTTP/1.1" 404 2106
WARNING 2018-10-23 22:18:00,174 base 152 Not Found: /favicon.ico
WARNING 2018-10-23 22:18:00,176 basehttp 124 "GET /favicon.ico HTTP/1.1" 404 2157
WARNING 2018-10-23 22:18:35,688 base 152 Not Found: /mobiles/16625139066/count/
WARNING 2018-10-23 22:18:35,698 basehttp 124 "GET /mobiles/16625139066/count/ HTTP/1.1" 404 2202
ERROR 2018-10-23 22:18:35,705 exception 80 Invalid HTTP_HOST header: '127.0.0.1:8000'. You may need to add '127.0.0.1' to ALLOWED_HOSTS.
WARNING 2018-10-23 22:18:35,818 basehttp 124 "GET /sms_code/16625139066/ HTTP/1.1" 400 70744
WARNING 2018-10-23 22:20:19,904 base 152 Not Found: /mobiles/16625139066/count/
WARNING 2018-10-23 22:20:19,915 basehttp 124 "GET /mobiles/16625139066/count/ HTTP/1.1" 404 2202
WARNING 2018-10-23 22:20:19,948 base 152 Not Found: /mobiles/16625139066/count/
ERROR 2018-10-23 22:20:19,951 exception 80 Invalid HTTP_HOST header: '127.0.0.1:8000'. You may need to add '127.0.0.1' to ALLOWED_HOSTS.
WARNING 2018-10-23 22:20:19,955 basehttp 124 "GET /mobiles/16625139066/count/ HTTP/1.1" 404 2202
WARNING 2018-10-23 22:20:20,061 basehttp 124 "GET /sms_code/16625139066/ HTTP/1.1" 400 70695
WARNING 2018-10-24 08:22:49,413 base 152 Not Found: /mobiles/16625139066/count/
WARNING 2018-10-24 08:22:49,426 basehttp 124 "GET /mobiles/16625139066/count/ HTTP/1.1" 404 2202
WARNING 2018-10-24 08:22:49,435 base 152 Not Found: /mobiles/16625139066/count/
WARNING 2018-10-24 08:22:49,442 basehttp 124 "GET /mobiles/16625139066/count/ HTTP/1.1" 404 2202
INFO 2018-10-24 08:22:49,569 basehttp 124 "GET /sms_code/16625139066/ HTTP/1.1" 200 16
WARNING 2018-10-24 08:28:59,280 base 152 Not Found: /mobiles/16625139066/count/
WARNING 2018-10-24 08:28:59,296 basehttp 124 "GET /mobiles/16625139066/count/ HTTP/1.1" 404 2202
INFO 2018-10-24 08:28:59,292 basehttp 124 "GET /sms_code/16625139066/ HTTP/1.1" 200 16
WARNING 2018-10-24 20:33:28,665 base 152 Not Found: /usernames/16625139066/count/
WARNING 2018-10-24 20:33:28,669 basehttp 124 "GET /usernames/16625139066/count/ HTTP/1.1" 404 2208
INFO 2018-10-24 20:34:57,572 basehttp 124 "GET /usernames/16625139066/count/ HTTP/1.1" 200 36
INFO 2018-10-24 20:37:30,650 basehttp 124 "GET /usernames/16625139066/count/ HTTP/1.1" 200 36
INFO 2018-10-24 20:39:24,444 basehttp 124 "GET /mobiles/16625139066/count/ HTTP/1.1" 200 34
INFO 2018-10-24 20:40:01,257 basehttp 124 "GET /usernames/16625139066/count/ HTTP/1.1" 200 36
INFO 2018-10-24 20:40:13,330 basehttp 124 "GET /mobiles/16625139066/count/ HTTP/1.1" 200 34
INFO 2018-10-24 21:07:37,996 basehttp 124 "GET /usernames/16625139066/count/ HTTP/1.1" 200 36
INFO 2018-10-24 21:07:49,366 basehttp 124 "GET /mobiles/16625139066/count/ HTTP/1.1" 200 34
INFO 2018-10-24 21:07:49,430 basehttp 124 "GET /mobiles/16625139066/count/ HTTP/1.1" 200 34
INFO 2018-10-24 21:07:49,649 basehttp 124 "GET /sms_code/16625139066/ HTTP/1.1" 200 16
INFO 2018-10-24 21:08:03,493 basehttp 124 "OPTIONS /users/ HTTP/1.1" 200 0
INFO 2018-10-24 21:08:03,499 basehttp 124 "GET /usernames/16625139066/count/ HTTP/1.1" 200 36
INFO 2018-10-24 21:08:03,511 basehttp 124 "GET /mobiles/16625139066/count/ HTTP/1.1" 200 34
WARNING 2018-10-24 21:08:03,530 base 152 Not Found: /users/
WARNING 2018-10-24 21:08:03,531 basehttp 124 "POST /users/ HTTP/1.1" 404 2687
INFO 2018-10-24 21:08:40,683 basehttp 124 "GET /mobiles/16625139066/count/ HTTP/1.1" 200 34
INFO 2018-10-24 21:08:40,704 basehttp 124 "GET /usernames/16625139066/count/ HTTP/1.1" 200 36
ERROR 2018-10-24 21:08:40,717 exception 135 Internal Server Error: /users/
Traceback (most recent call last):
  File "/home/python/.virtualenvs/mydjango_py3_1.11/lib/python3.5/site-packages/django/core/handlers/exception.py", line 41, in inner
    response = get_response(request)
  File "/home/python/.virtualenvs/mydjango_py3_1.11/lib/python3.5/site-packages/django/core/handlers/base.py", line 187, in _get_response
    response = self.process_exception_by_middleware(e, request)
  File "/home/python/.virtualenvs/mydjango_py3_1.11/lib/python3.5/site-packages/django/core/handlers/base.py", line 185, in _get_response
    response = wrapped_callback(request, *callback_args, **callback_kwargs)
  File "/home/python/.virtualenvs/mydjango_py3_1.11/lib/python3.5/site-packages/django/views/decorators/csrf.py", line 58, in wrapped_view
    return view_func(*args, **kwargs)
  File "/home/python/.virtualenvs/mydjango_py3_1.11/lib/python3.5/site-packages/django/views/generic/base.py", line 68, in view
    return self.dispatch(request, *args, **kwargs)
  File "/home/python/.virtualenvs/mydjango_py3_1.11/lib/python3.5/site-packages/rest_framework/views.py", line 483, in dispatch
    response = self.handle_exception(exc)
  File "/home/python/.virtualenvs/mydjango_py3_1.11/lib/python3.5/site-packages/rest_framework/views.py", line 443, in handle_exception
    self.raise_uncaught_exception(exc)
  File "/home/python/.virtualenvs/mydjango_py3_1.11/lib/python3.5/site-packages/rest_framework/views.py", line 480, in dispatch
    response = handler(request, *args, **kwargs)
  File "/home/python/.virtualenvs/mydjango_py3_1.11/lib/python3.5/site-packages/rest_framework/generics.py", line 192, in post
    return self.create(request, *args, **kwargs)
  File "/home/python/.virtualenvs/mydjango_py3_1.11/lib/python3.5/site-packages/rest_framework/mixins.py", line 20, in create
    serializer.is_valid(raise_exception=True)
  File "/home/python/.virtualenvs/mydjango_py3_1.11/lib/python3.5/site-packages/rest_framework/serializers.py", line 236, in is_valid
    self._validated_data = self.run_validation(self.initial_data)
  File "/home/python/.virtualenvs/mydjango_py3_1.11/lib/python3.5/site-packages/rest_framework/serializers.py", line 434, in run_validation
    value = self.to_internal_value(data)
  File "/home/python/.virtualenvs/mydjango_py3_1.11/lib/python3.5/site-packages/rest_framework/serializers.py", line 490, in to_internal_value
    validated_value = validate_method(validated_value)
  File "/home/python/Desktop/MyProject/meiduo/meiduo/apps/users/serializers.py", line 61, in validate_allow
    raise value
TypeError: exceptions must derive from BaseException
ERROR 2018-10-24 21:08:40,864 basehttp 124 "POST /users/ HTTP/1.1" 500 18803
INFO 2018-10-24 21:10:24,054 basehttp 124 "GET /mobiles/16625139066/count/ HTTP/1.1" 200 34
INFO 2018-10-24 21:10:24,309 basehttp 124 "GET /sms_code/16625139066/ HTTP/1.1" 200 16
ERROR 2018-10-24 21:10:32,786 exception 135 Internal Server Error: /users/
Traceback (most recent call last):
  File "/home/python/.virtualenvs/mydjango_py3_1.11/lib/python3.5/site-packages/django/core/handlers/exception.py", line 41, in inner
    response = get_response(request)
  File "/home/python/.virtualenvs/mydjango_py3_1.11/lib/python3.5/site-packages/django/core/handlers/base.py", line 187, in _get_response
    response = self.process_exception_by_middleware(e, request)
  File "/home/python/.virtualenvs/mydjango_py3_1.11/lib/python3.5/site-packages/django/core/handlers/base.py", line 185, in _get_response
    response = wrapped_callback(request, *callback_args, **callback_kwargs)
  File "/home/python/.virtualenvs/mydjango_py3_1.11/lib/python3.5/site-packages/django/views/decorators/csrf.py", line 58, in wrapped_view
    return view_func(*args, **kwargs)
  File "/home/python/.virtualenvs/mydjango_py3_1.11/lib/python3.5/site-packages/django/views/generic/base.py", line 68, in view
    return self.dispatch(request, *args, **kwargs)
  File "/home/python/.virtualenvs/mydjango_py3_1.11/lib/python3.5/site-packages/rest_framework/views.py", line 483, in dispatch
    response = self.handle_exception(exc)
  File "/home/python/.virtualenvs/mydjango_py3_1.11/lib/python3.5/site-packages/rest_framework/views.py", line 443, in handle_exception
    self.raise_uncaught_exception(exc)
  File "/home/python/.virtualenvs/mydjango_py3_1.11/lib/python3.5/site-packages/rest_framework/views.py", line 480, in dispatch
    response = handler(request, *args, **kwargs)
  File "/home/python/.virtualenvs/mydjango_py3_1.11/lib/python3.5/site-packages/rest_framework/generics.py", line 192, in post
    return self.create(request, *args, **kwargs)
  File "/home/python/.virtualenvs/mydjango_py3_1.11/lib/python3.5/site-packages/rest_framework/mixins.py", line 20, in create
    serializer.is_valid(raise_exception=True)
  File "/home/python/.virtualenvs/mydjango_py3_1.11/lib/python3.5/site-packages/rest_framework/serializers.py", line 236, in is_valid
    self._validated_data = self.run_validation(self.initial_data)
  File "/home/python/.virtualenvs/mydjango_py3_1.11/lib/python3.5/site-packages/rest_framework/serializers.py", line 434, in run_validation
    value = self.to_internal_value(data)
  File "/home/python/.virtualenvs/mydjango_py3_1.11/lib/python3.5/site-packages/rest_framework/serializers.py", line 490, in to_internal_value
    validated_value = validate_method(validated_value)
  File "/home/python/Desktop/MyProject/meiduo/meiduo/apps/users/serializers.py", line 61, in validate_allow
    raise value
TypeError: exceptions must derive from BaseException
INFO 2018-10-24 21:10:32,843 basehttp 124 "GET /usernames/16625139066/count/ HTTP/1.1" 200 36
ERROR 2018-10-24 21:10:32,871 basehttp 124 "POST /users/ HTTP/1.1" 500 18803
INFO 2018-10-24 21:10:32,875 basehttp 124 "GET /mobiles/16625139066/count/ HTTP/1.1" 200 34
INFO 2018-10-24 21:14:09,063 basehttp 124 "GET /mobiles/16625139066/count/ HTTP/1.1" 200 34
INFO 2018-10-24 21:14:09,175 basehttp 124 "GET /sms_code/16625139066/ HTTP/1.1" 200 16
INFO 2018-10-24 21:14:18,755 basehttp 124 "GET /usernames/16625139066/count/ HTTP/1.1" 200 36
INFO 2018-10-24 21:14:18,763 basehttp 124 "GET /mobiles/16625139066/count/ HTTP/1.1" 200 34
INFO 2018-10-24 21:14:18,868 basehttp 124 "POST /users/ HTTP/1.1" 201 236
ERROR 2018-10-24 21:58:44,664 exception 80 Invalid HTTP_HOST header: '127.0.0.1:8000'. You may need to add '127.0.0.1' to ALLOWED_HOSTS.
WARNING 2018-10-24 21:58:44,789 basehttp 124 "GET / HTTP/1.1" 400 70744
ERROR 2018-10-24 21:58:45,300 exception 80 Invalid HTTP_HOST header: '127.0.0.1:8000'. You may need to add '127.0.0.1' to ALLOWED_HOSTS.
WARNING 2018-10-24 21:58:45,367 basehttp 124 "GET /favicon.ico HTTP/1.1" 400 70797
WARNING 2018-10-24 21:59:23,360 base 152 Not Found: /
WARNING 2018-10-24 21:59:23,378 basehttp 124 "GET / HTTP/1.1" 404 2645
WARNING 2018-10-24 21:59:23,731 base 152 Not Found: /favicon.ico
WARNING 2018-10-24 21:59:23,739 basehttp 124 "GET /favicon.ico HTTP/1.1" 404 2696
INFO 2018-10-24 21:59:27,085 basehttp 124 "GET /users HTTP/1.1" 301 0
WARNING 2018-10-24 21:59:27,237 basehttp 124 "GET /users/ HTTP/1.1" 405 8462
INFO 2018-10-24 21:59:27,264 basehttp 124 "GET /static/rest_framework/css/bootstrap.min.css HTTP/1.1" 200 121200
INFO 2018-10-24 21:59:27,311 basehttp 124 "GET /static/rest_framework/css/bootstrap-tweaks.css HTTP/1.1" 200 3385
INFO 2018-10-24 21:59:27,335 basehttp 124 "GET /static/rest_framework/css/default.css HTTP/1.1" 200 1131
INFO 2018-10-24 21:59:27,336 basehttp 124 "GET /static/rest_framework/css/prettify.css HTTP/1.1" 200 817
INFO 2018-10-24 21:59:27,416 basehttp 124 "GET /static/rest_framework/js/ajax-form.js HTTP/1.1" 200 3597
INFO 2018-10-24 21:59:27,429 basehttp 124 "GET /static/rest_framework/js/csrf.js HTTP/1.1" 200 1735
INFO 2018-10-24 21:59:27,462 basehttp 124 "GET /static/rest_framework/js/default.js HTTP/1.1" 200 1262
INFO 2018-10-24 21:59:27,463 basehttp 124 "GET /static/rest_framework/js/jquery-3.3.1.min.js HTTP/1.1" 200 86927
INFO 2018-10-24 21:59:27,471 basehttp 124 "GET /static/rest_framework/js/prettify-min.js HTTP/1.1" 200 13632
INFO 2018-10-24 21:59:27,527 basehttp 124 "GET /static/rest_framework/img/grid.png HTTP/1.1" 200 1458
INFO 2018-10-24 21:59:27,530 basehttp 124 "GET /static/rest_framework/js/bootstrap.min.js HTTP/1.1" 200 37045
WARNING 2018-10-24 22:00:22,753 base 152 Not Found: /sms_codes/18812345678
WARNING 2018-10-24 22:00:22,762 basehttp 124 "GET /sms_codes/18812345678 HTTP/1.1" 404 2726
INFO 2018-10-24 22:00:30,638 basehttp 124 "GET /sms_code/18812345678 HTTP/1.1" 301 0
INFO 2018-10-24 22:00:30,878 basehttp 124 "GET /sms_code/18812345678/ HTTP/1.1" 200 5170
ERROR 2018-10-24 22:01:19,608 exception 135 Internal Server Error: /users/
Traceback (most recent call last):
  File "/home/python/.virtualenvs/mydjango_py3_1.11/lib/python3.5/site-packages/django/core/handlers/exception.py", line 41, in inner
    response = get_response(request)
  File "/home/python/.virtualenvs/mydjango_py3_1.11/lib/python3.5/site-packages/django/core/handlers/base.py", line 187, in _get_response
    response = self.process_exception_by_middleware(e, request)
  File "/home/python/.virtualenvs/mydjango_py3_1.11/lib/python3.5/site-packages/django/core/handlers/base.py", line 185, in _get_response
    response = wrapped_callback(request, *callback_args, **callback_kwargs)
  File "/home/python/.virtualenvs/mydjango_py3_1.11/lib/python3.5/site-packages/django/views/decorators/csrf.py", line 58, in wrapped_view
    return view_func(*args, **kwargs)
  File "/home/python/.virtualenvs/mydjango_py3_1.11/lib/python3.5/site-packages/django/views/generic/base.py", line 68, in view
    return self.dispatch(request, *args, **kwargs)
  File "/home/python/.virtualenvs/mydjango_py3_1.11/lib/python3.5/site-packages/rest_framework/views.py", line 483, in dispatch
    response = self.handle_exception(exc)
  File "/home/python/.virtualenvs/mydjango_py3_1.11/lib/python3.5/site-packages/rest_framework/views.py", line 443, in handle_exception
    self.raise_uncaught_exception(exc)
  File "/home/python/.virtualenvs/mydjango_py3_1.11/lib/python3.5/site-packages/rest_framework/views.py", line 480, in dispatch
    response = handler(request, *args, **kwargs)
  File "/home/python/.virtualenvs/mydjango_py3_1.11/lib/python3.5/site-packages/rest_framework/generics.py", line 192, in post
    return self.create(request, *args, **kwargs)
  File "/home/python/.virtualenvs/mydjango_py3_1.11/lib/python3.5/site-packages/rest_framework/mixins.py", line 20, in create
    serializer.is_valid(raise_exception=True)
  File "/home/python/.virtualenvs/mydjango_py3_1.11/lib/python3.5/site-packages/rest_framework/serializers.py", line 236, in is_valid
    self._validated_data = self.run_validation(self.initial_data)
  File "/home/python/.virtualenvs/mydjango_py3_1.11/lib/python3.5/site-packages/rest_framework/serializers.py", line 437, in run_validation
    value = self.validate(value)
  File "/home/python/Desktop/MyProject/meiduo/meiduo/apps/users/serializers.py", line 76, in validate
    if int(sms_code_redis) != int(sms_code_request):
TypeError: int() argument must be a string, a bytes-like object or a number, not 'NoneType'
ERROR 2018-10-24 22:01:19,792 basehttp 124 "POST /users/ HTTP/1.1" 500 120809
INFO 2018-10-24 22:03:26,313 basehttp 124 "GET /sms_code/18812345678/ HTTP/1.1" 200 5170
INFO 2018-10-24 22:03:26,367 basehttp 124 "GET /static/rest_framework/css/bootstrap.min.css HTTP/1.1" 304 0
INFO 2018-10-24 22:03:26,369 basehttp 124 "GET /static/rest_framework/css/bootstrap-tweaks.css HTTP/1.1" 304 0
INFO 2018-10-24 22:03:26,379 basehttp 124 "GET /static/rest_framework/css/prettify.css HTTP/1.1" 304 0
INFO 2018-10-24 22:03:26,383 basehttp 124 "GET /static/rest_framework/css/default.css HTTP/1.1" 304 0
INFO 2018-10-24 22:03:26,607 basehttp 124 "GET /static/rest_framework/js/bootstrap.min.js HTTP/1.1" 304 0
INFO 2018-10-24 22:03:26,608 basehttp 124 "GET /static/rest_framework/js/prettify-min.js HTTP/1.1" 304 0
INFO 2018-10-24 22:03:26,612 basehttp 124 "GET /static/rest_framework/js/jquery-3.3.1.min.js HTTP/1.1" 304 0
INFO 2018-10-24 22:03:26,617 basehttp 124 "GET /static/rest_framework/js/csrf.js HTTP/1.1" 304 0
INFO 2018-10-24 22:03:26,625 basehttp 124 "GET /static/rest_framework/js/ajax-form.js HTTP/1.1" 304 0
INFO 2018-10-24 22:03:26,651 basehttp 124 "GET /static/rest_framework/js/default.js HTTP/1.1" 304 0
ERROR 2018-10-24 22:03:31,445 exception 135 Internal Server Error: /users/
Traceback (most recent call last):
  File "/home/python/.virtualenvs/mydjango_py3_1.11/lib/python3.5/site-packages/django/core/handlers/exception.py", line 41, in inner
    response = get_response(request)
  File "/home/python/.virtualenvs/mydjango_py3_1.11/lib/python3.5/site-packages/django/core/handlers/base.py", line 187, in _get_response
    response = self.process_exception_by_middleware(e, request)
  File "/home/python/.virtualenvs/mydjango_py3_1.11/lib/python3.5/site-packages/django/core/handlers/base.py", line 185, in _get_response
    response = wrapped_callback(request, *callback_args, **callback_kwargs)
  File "/home/python/.virtualenvs/mydjango_py3_1.11/lib/python3.5/site-packages/django/views/decorators/csrf.py", line 58, in wrapped_view
    return view_func(*args, **kwargs)
  File "/home/python/.virtualenvs/mydjango_py3_1.11/lib/python3.5/site-packages/django/views/generic/base.py", line 68, in view
    return self.dispatch(request, *args, **kwargs)
  File "/home/python/.virtualenvs/mydjango_py3_1.11/lib/python3.5/site-packages/rest_framework/views.py", line 483, in dispatch
    response = self.handle_exception(exc)
  File "/home/python/.virtualenvs/mydjango_py3_1.11/lib/python3.5/site-packages/rest_framework/views.py", line 443, in handle_exception
    self.raise_uncaught_exception(exc)
  File "/home/python/.virtualenvs/mydjango_py3_1.11/lib/python3.5/site-packages/rest_framework/views.py", line 480, in dispatch
    response = handler(request, *args, **kwargs)
  File "/home/python/.virtualenvs/mydjango_py3_1.11/lib/python3.5/site-packages/rest_framework/generics.py", line 192, in post
    return self.create(request, *args, **kwargs)
  File "/home/python/.virtualenvs/mydjango_py3_1.11/lib/python3.5/site-packages/rest_framework/mixins.py", line 20, in create
    serializer.is_valid(raise_exception=True)
  File "/home/python/.virtualenvs/mydjango_py3_1.11/lib/python3.5/site-packages/rest_framework/serializers.py", line 236, in is_valid
    self._validated_data = self.run_validation(self.initial_data)
  File "/home/python/.virtualenvs/mydjango_py3_1.11/lib/python3.5/site-packages/rest_framework/serializers.py", line 437, in run_validation
    value = self.validate(value)
  File "/home/python/Desktop/MyProject/meiduo/meiduo/apps/users/serializers.py", line 76, in validate
    if int(sms_code_redis) != int(sms_code_request):
TypeError: int() argument must be a string, a bytes-like object or a number, not 'NoneType'
ERROR 2018-10-24 22:03:31,714 basehttp 124 "POST /users/ HTTP/1.1" 500 120809
INFO 2018-10-24 22:04:00,233 basehttp 124 "POST /users/ HTTP/1.1" 201 8727
WARNING 2018-10-24 22:12:10,363 basehttp 124 "GET /static/rest_framework/css/bootstrap.min.css.map HTTP/1.1" 404 1733
INFO 2018-10-26 21:49:19,146 basehttp 124 "OPTIONS /authorizations/ HTTP/1.1" 200 0
WARNING 2018-10-26 21:49:19,232 base 152 Not Found: /authorizations/
WARNING 2018-10-26 21:49:19,238 basehttp 124 "POST /authorizations/ HTTP/1.1" 404 2823
WARNING 2018-10-26 21:49:26,276 base 152 Not Found: /authorizations/
WARNING 2018-10-26 21:49:26,281 basehttp 124 "POST /authorizations/ HTTP/1.1" 404 2823
WARNING 2018-10-26 21:51:36,152 base 152 Not Found: /authorizations/
WARNING 2018-10-26 21:51:36,165 basehttp 124 "POST /authorizations/ HTTP/1.1" 404 2823
WARNING 2018-10-26 21:52:22,825 base 152 Not Found: /authorizations/
WARNING 2018-10-26 21:52:22,835 basehttp 124 "POST /authorizations/ HTTP/1.1" 404 2822
WARNING 2018-10-26 21:52:38,386 base 152 Not Found: /authorizations/
WARNING 2018-10-26 21:52:38,416 basehttp 124 "POST /authorizations/ HTTP/1.1" 404 2822
WARNING 2018-10-26 21:53:38,702 base 152 Not Found: /authorizations/
WARNING 2018-10-26 21:53:38,704 basehttp 124 "POST /authorizations/ HTTP/1.1" 404 2822
WARNING 2018-10-26 21:55:49,978 base 152 Not Found: /authorizations/
WARNING 2018-10-26 21:55:49,982 basehttp 124 "POST /authorizations/ HTTP/1.1" 404 2822
WARNING 2018-10-26 21:56:09,886 base 152 Not Found: /authorizations/
WARNING 2018-10-26 21:56:09,887 basehttp 124 "POST /authorizations/ HTTP/1.1" 404 2822
WARNING 2018-10-26 21:57:37,493 base 152 Not Found: /authorizations/
WARNING 2018-10-26 21:57:37,494 basehttp 124 "POST /authorizations/ HTTP/1.1" 404 2822
INFO 2018-10-26 22:37:23,094 basehttp 124 "OPTIONS /authorizations/ HTTP/1.1" 200 0
WARNING 2018-10-26 22:37:23,236 base 152 Not Found: /authorizations/
WARNING 2018-10-26 22:37:23,242 basehttp 124 "POST /authorizations/ HTTP/1.1" 404 2822
WARNING 2018-10-26 22:45:14,262 base 152 Not Found: /authorizations/
WARNING 2018-10-26 22:45:14,272 basehttp 124 "POST /authorizations/ HTTP/1.1" 404 2822
INFO 2018-10-26 22:56:13,943 basehttp 124 "OPTIONS /authorizations/ HTTP/1.1" 200 0
INFO 2018-10-26 22:56:14,254 basehttp 124 "POST /authorizations/ HTTP/1.1" 200 179
INFO 2018-10-26 23:01:40,488 basehttp 124 "POST /authorizations/ HTTP/1.1" 200 214
INFO 2018-10-26 23:08:16,356 basehttp 124 "OPTIONS /authorizations/ HTTP/1.1" 200 0
INFO 2018-10-26 23:08:16,637 basehttp 124 "POST /authorizations/ HTTP/1.1" 200 214
